Workbook
Name Correlation_Options: 'Data Validation Sources'!$C$2:$C$6
Name Min_Max_or_Target_Options: 'Data Validation Sources'!$A$2:$A$5
Name Relationship_Between_Requirements_Options: 'Data Validation Sources'!$B$2:$B$5

Sheet House of Quality 1
B2: Title: | CY2: Legend
B5: Author: | CY5: Θ | CZ5: Strong Relationship | DE5: 9
B8: Date: | CY8: Ο | CZ8: Moderate Relationship | DE8: 3
B11: Notes: | CY11: ▲ | CZ11: Weak Relationship | DE11: 1
CY14: ┼┼ | CZ14: Strong Positive Correlation
CY17: ┼ | CZ17: Positive Correlation
CY20: ▬ | CZ20: Negative Correlation
CY23: ▼ | CZ23: Strong Negative Correlation
CY26: ▼ | CZ26: Objective Is To Minimize
CY29: ▲ | CZ29: Objective Is To Maximize
CY32: x | CZ32: Objective Is To Hit Target
F47: Column # | H47: 1 | N47: 2 | T47: 3 | Z47: 4 | AF47: 5 | AL47: 6 | AR47: 7 | AX47: 8 | BD47: 9 | BJ47: 10 | BP47: 11 | BV47: 12 | CB47: 13 | CH47: 14 | CN47: 15
F48: Direction of Improvement: Minimize (▼), Maximize (▲), or Target (x) | CT48: Competitive Analysis (0=Worst, 5=Best)
B49: Row # | C49: Max Relationship Value in Row | D49: Relative Weight | E49: Weight / Importance | G49: Quality Characteristics (a.k.a. "Functional Requirements" or "Hows") | CT49: Our Company | CU49: Competitor 1 | CV49: Competitor 2 | CW49: Competitor 3 | CX49: Competitor 4 | CY49: Competitor 5 | DG49: Chart Axis Values
F50: Demanded Quality (a.k.a. "Customer Requirements" or "Whats") | CZ50: 0 | DA50: 1 | DB50: 2 | DC50: 3 | DD50: 4 | DE50: 5
B51: 1 | C51: =MAX($H69:$CS69) -> 0 | D51: =IF(ISNUMBER($E51), ($E51/SUM($E$51:$E$60))*100, "") | DG51: =(ROWS($B$51:$B$60)-ROW()+ROW($B$51:$B$60)-0.5)/ROWS($B$51:$B$60) -> 0.95
B52: 2 | C52: =MAX($H70:$CS70) -> 0 | D52: =IF(ISNUMBER($E52), ($E52/SUM($E$51:$E$60))*100, "") | DG52: =(ROWS($B$51:$B$60)-ROW()+ROW($B$51:$B$60)-0.5)/ROWS($B$51:$B$60) -> 0.85
B53: 3 | C53: =MAX($H71:$CS71) -> 0 | D53: =IF(ISNUMBER($E53), ($E53/SUM($E$51:$E$60))*100, "") | DG53: =(ROWS($B$51:$B$60)-ROW()+ROW($B$51:$B$60)-0.5)/ROWS($B$51:$B$60) -> 0.75
B54: 4 | C54: =MAX($H72:$CS72) -> 0 | D54: =IF(ISNUMBER($E54), ($E54/SUM($E$51:$E$60))*100, "") | DG54: =(ROWS($B$51:$B$60)-ROW()+ROW($B$51:$B$60)-0.5)/ROWS($B$51:$B$60) -> 0.65
B55: 5 | C55: =MAX($H73:$CS73) -> 0 | D55: =IF(ISNUMBER($E55), ($E55/SUM($E$51:$E$60))*100, "") | DG55: =(ROWS($B$51:$B$60)-ROW()+ROW($B$51:$B$60)-0.5)/ROWS($B$51:$B$60) -> 0.55
B56: 6 | C56: =MAX($H74:$CS74) -> 0 | D56: =IF(ISNUMBER($E56), ($E56/SUM($E$51:$E$60))*100, "") | DG56: =(ROWS($B$51:$B$60)-ROW()+ROW($B$51:$B$60)-0.5)/ROWS($B$51:$B$60) -> 0.45
B57: 7 | C57: =MAX($H75:$CS75) -> 0 | D57: =IF(ISNUMBER($E57), ($E57/SUM($E$51:$E$60))*100, "") | DG57: =(ROWS($B$51:$B$60)-ROW()+ROW($B$51:$B$60)-0.5)/ROWS($B$51:$B$60) -> 0.35
B58: 8 | C58: =MAX($H76:$CS76) -> 0 | D58: =IF(ISNUMBER($E58), ($E58/SUM($E$51:$E$60))*100, "") | DG58: =(ROWS($B$51:$B$60)-ROW()+ROW($B$51:$B$60)-0.5)/ROWS($B$51:$B$60) -> 0.25
B59: 9 | C59: =MAX($H77:$CS77) -> 0 | D59: =IF(ISNUMBER($E59), ($E59/SUM($E$51:$E$60))*100, "") | DG59: =(ROWS($B$51:$B$60)-ROW()+ROW($B$51:$B$60)-0.5)/ROWS($B$51:$B$60) -> 0.15
B60: 10 | C60: =MAX($H78:$CS78) -> 0 | D60: =IF(ISNUMBER($E60), ($E60/SUM($E$51:$E$60))*100, "") | DG60: =(ROWS($B$51:$B$60)-ROW()+ROW($B$51:$B$60)-0.5)/ROWS($B$51:$B$60) -> 0.05
F61: Target or Limit Value
F62: Difficulty (0=Easy to Accomplish, 10=Extremely Difficult)
F63: Max Relationship Value in Column | H63: =MAX(H69:M78) -> 0 | N63: =MAX(N69:S78) -> 0 | T63: =MAX(T69:Y78) -> 0 | Z63: =MAX(Z69:AE78) -> 0 | AF63: =MAX(AF69:AK78) -> 0 | AL63: =MAX(AL69:AQ78) -> 0 | AR63: =MAX(AR69:AW78) -> 0 | AX63: =MAX(AX69:BC78) -> 0 | BD63: =MAX(BD69:BI78) -> 0 | BJ63: =MAX(BJ69:BO78) -> 0 | BP63: =MAX(BP69:BU78) -> 0 | BV63: =MAX(BV69:CA78) -> 0 | CB63: =MAX(CB69:CG78) -> 0 | CH63: =MAX(CH69:CM78) -> 0 | CN63: =MAX(CN69:CS78) -> 0
F64: Weight / Importance | H64: =SUM($D69*H69,$D70*H70,$D71*H71,$D72*H72,$D73*H73,$D74*H74,$D75*H75,$D76*H76,$D77*H77,$D78*H78) -> 0 | N64: =SUM($D69*N69,$D70*N70,$D71*N71,$D72*N72,$D73*N73,$D74*N74,$D75*N75,$D76*N76,$D77*N77,$D78*N78) -> 0 | T64: =SUM($D69*T69,$D70*T70,$D71*T71,$D72*T72,$D73*T73,$D74*T74,$D75*T75,$D76*T76,$D77*T77,$D78*T78) -> 0 | Z64: =SUM($D69*Z69,$D70*Z70,$D71*Z71,$D72*Z72,$D73*Z73,$D74*Z74,$D75*Z75,$D76*Z76,$D77*Z77,$D78*Z78) -> 0 | AF64: =SUM($D69*AF69,$D70*AF70,$D71*AF71,$D72*AF72,$D73*AF73,$D74*AF74,$D75*AF75,$D76*AF76,$D77*AF77,$D78*AF78) -> 0 | AL64: =SUM($D69*AL69,$D70*AL70,$D71*AL71,$D72*AL72,$D73*AL73,$D74*AL74,$D75*AL75,$D76*AL76,$D77*AL77,$D78*AL78) -> 0 | AR64: =SUM($D69*AR69,$D70*AR70,$D71*AR71,$D72*AR72,$D73*AR73,$D74*AR74,$D75*AR75,$D76*AR76,$D77*AR77,$D78*AR78) -> 0 | AX64: =SUM($D69*AX69,$D70*AX70,$D71*AX71,$D72*AX72,$D73*AX73,$D74*AX74,$D75*AX75,$D76*AX76,$D77*AX77,$D78*AX78) -> 0 | BD64: =SUM($D69*BD69,$D70*BD70,$D71*BD71,$D72*BD72,$D73*BD73,$D74*BD74,$D75*BD75,$D76*BD76,$D77*BD77,$D78*BD78) -> 0 | BJ64: =SUM($D69*BJ69,$D70*BJ70,$D71*BJ71,$D72*BJ72,$D73*BJ73,$D74*BJ74,$D75*BJ75,$D76*BJ76,$D77*BJ77,$D78*BJ78) -> 0 | BP64: =SUM($D69*BP69,$D70*BP70,$D71*BP71,$D72*BP72,$D73*BP73,$D74*BP74,$D75*BP75,$D76*BP76,$D77*BP77,$D78*BP78) -> 0 | BV64: =SUM($D69*BV69,$D70*BV70,$D71*BV71,$D72*BV72,$D73*BV73,$D74*BV74,$D75*BV75,$D76*BV76,$D77*BV77,$D78*BV78) -> 0 | CB64: =SUM($D69*CB69,$D70*CB70,$D71*CB71,$D72*CB72,$D73*CB73,$D74*CB74,$D75*CB75,$D76*CB76,$D77*CB77,$D78*CB78) -> 0 | CH64: =SUM($D69*CH69,$D70*CH70,$D71*CH71,$D72*CH72,$D73*CH73,$D74*CH74,$D75*CH75,$D76*CH76,$D77*CH77,$D78*CH78) -> 0 | CN64: =SUM($D69*CN69,$D70*CN70,$D71*CN71,$D72*CN72,$D73*CN73,$D74*CN74,$D75*CN75,$D76*CN76,$D77*CN77,$D78*CN78) -> 0
F65: Relative Weight | H65: =IF(H$64>0,(H$64/SUM($64:$64))*100, "") | N65: =IF(N$64>0,(N$64/SUM($64:$64))*100, "") | T65: =IF(T$64>0,(T$64/SUM($64:$64))*100, "") | Z65: =IF(Z$64>0,(Z$64/SUM($64:$64))*100, "") | AF65: =IF(AF$64>0,(AF$64/SUM($64:$64))*100, "") | AL65: =IF(AL$64>0,(AL$64/SUM($64:$64))*100, "") | AR65: =IF(AR$64>0,(AR$64/SUM($64:$64))*100, "") | AX65: =IF(AX$64>0,(AX$64/SUM($64:$64))*100, "") | BD65: =IF(BD$64>0,(BD$64/SUM($64:$64))*100, "") | BJ65: =IF(BJ$64>0,(BJ$64/SUM($64:$64))*100, "") | BP65: =IF(BP$64>0,(BP$64/SUM($64:$64))*100, "") | BV65: =IF(BV$64>0,(BV$64/SUM($64:$64))*100, "") | CB65: =IF(CB$64>0,(CB$64/SUM($64:$64))*100, "") | CH65: =IF(CH$64>0,(CH$64/SUM($64:$64))*100, "") | CN65: =IF(CN$64>0,(CN$64/SUM($64:$64))*100, "") | CU65: Powered by QFD Online (http://www.QFDOnline.com)
D68: Numeric Values for Relationship Matrix Calculations
D69: =IF($D51<>"",$D51,0) -> 0 | H69: =IF(H51="Θ", 9, IF(H51="Ο", 3, IF(H51="▲", 1, "0"))) -> 0 | N69: =IF(N51="Θ", 9, IF(N51="Ο", 3, IF(N51="▲", 1, "0"))) -> 0 | T69: =IF(T51="Θ", 9, IF(T51="Ο", 3, IF(T51="▲", 1, "0"))) -> 0 | Z69: =IF(Z51="Θ", 9, IF(Z51="Ο", 3, IF(Z51="▲", 1, "0"))) -> 0 | AF69: =IF(AF51="Θ", 9, IF(AF51="Ο", 3, IF(AF51="▲", 1, "0"))) -> 0 | AL69: =IF(AL51="Θ", 9, IF(AL51="Ο", 3, IF(AL51="▲", 1, "0"))) -> 0 | AR69: =IF(AR51="Θ", 9, IF(AR51="Ο", 3, IF(AR51="▲", 1, "0"))) -> 0 | AX69: =IF(AX51="Θ", 9, IF(AX51="Ο", 3, IF(AX51="▲", 1, "0"))) -> 0 | BD69: =IF(BD51="Θ", 9, IF(BD51="Ο", 3, IF(BD51="▲", 1, "0"))) -> 0 | BJ69: =IF(BJ51="Θ", 9, IF(BJ51="Ο", 3, IF(BJ51="▲", 1, "0"))) -> 0 | BP69: =IF(BP51="Θ", 9, IF(BP51="Ο", 3, IF(BP51="▲", 1, "0"))) -> 0 | BV69: =IF(BV51="Θ", 9, IF(BV51="Ο", 3, IF(BV51="▲", 1, "0"))) -> 0 | CB69: =IF(CB51="Θ", 9, IF(CB51="Ο", 3, IF(CB51="▲", 1, "0"))) -> 0 | CH69: =IF(CH51="Θ", 9, IF(CH51="Ο", 3, IF(CH51="▲", 1, "0"))) -> 0 | CN69: =IF(CN51="Θ", 9, IF(CN51="Ο", 3, IF(CN51="▲", 1, "0"))) -> 0
D70: =IF($D52<>"",$D52,0) -> 0 | H70: =IF(H52="Θ", 9, IF(H52="Ο", 3, IF(H52="▲", 1, "0"))) -> 0 | N70: =IF(N52="Θ", 9, IF(N52="Ο", 3, IF(N52="▲", 1, "0"))) -> 0 | T70: =IF(T52="Θ", 9, IF(T52="Ο", 3, IF(T52="▲", 1, "0"))) -> 0 | Z70: =IF(Z52="Θ", 9, IF(Z52="Ο", 3, IF(Z52="▲", 1, "0"))) -> 0 | AF70: =IF(AF52="Θ", 9, IF(AF52="Ο", 3, IF(AF52="▲", 1, "0"))) -> 0 | AL70: =IF(AL52="Θ", 9, IF(AL52="Ο", 3, IF(AL52="▲", 1, "0"))) -> 0 | AR70: =IF(AR52="Θ", 9, IF(AR52="Ο", 3, IF(AR52="▲", 1, "0"))) -> 0 | AX70: =IF(AX52="Θ", 9, IF(AX52="Ο", 3, IF(AX52="▲", 1, "0"))) -> 0 | BD70: =IF(BD52="Θ", 9, IF(BD52="Ο", 3, IF(BD52="▲", 1, "0"))) -> 0 | BJ70: =IF(BJ52="Θ", 9, IF(BJ52="Ο", 3, IF(BJ52="▲", 1, "0"))) -> 0 | BP70: =IF(BP52="Θ", 9, IF(BP52="Ο", 3, IF(BP52="▲", 1, "0"))) -> 0 | BV70: =IF(BV52="Θ", 9, IF(BV52="Ο", 3, IF(BV52="▲", 1, "0"))) -> 0 | CB70: =IF(CB52="Θ", 9, IF(CB52="Ο", 3, IF(CB52="▲", 1, "0"))) -> 0 | CH70: =IF(CH52="Θ", 9, IF(CH52="Ο", 3, IF(CH52="▲", 1, "0"))) -> 0 | CN70: =IF(CN52="Θ", 9, IF(CN52="Ο", 3, IF(CN52="▲", 1, "0"))) -> 0
D71: =IF($D53<>"",$D53,0) -> 0 | H71: =IF(H53="Θ", 9, IF(H53="Ο", 3, IF(H53="▲", 1, "0"))) -> 0 | N71: =IF(N53="Θ", 9, IF(N53="Ο", 3, IF(N53="▲", 1, "0"))) -> 0 | T71: =IF(T53="Θ", 9, IF(T53="Ο", 3, IF(T53="▲", 1, "0"))) -> 0 | Z71: =IF(Z53="Θ", 9, IF(Z53="Ο", 3, IF(Z53="▲", 1, "0"))) -> 0 | AF71: =IF(AF53="Θ", 9, IF(AF53="Ο", 3, IF(AF53="▲", 1, "0"))) -> 0 | AL71: =IF(AL53="Θ", 9, IF(AL53="Ο", 3, IF(AL53="▲", 1, "0"))) -> 0 | AR71: =IF(AR53="Θ", 9, IF(AR53="Ο", 3, IF(AR53="▲", 1, "0"))) -> 0 | AX71: =IF(AX53="Θ", 9, IF(AX53="Ο", 3, IF(AX53="▲", 1, "0"))) -> 0 | BD71: =IF(BD53="Θ", 9, IF(BD53="Ο", 3, IF(BD53="▲", 1, "0"))) -> 0 | BJ71: =IF(BJ53="Θ", 9, IF(BJ53="Ο", 3, IF(BJ53="▲", 1, "0"))) -> 0 | BP71: =IF(BP53="Θ", 9, IF(BP53="Ο", 3, IF(BP53="▲", 1, "0"))) -> 0 | BV71: =IF(BV53="Θ", 9, IF(BV53="Ο", 3, IF(BV53="▲", 1, "0"))) -> 0 | CB71: =IF(CB53="Θ", 9, IF(CB53="Ο", 3, IF(CB53="▲", 1, "0"))) -> 0 | CH71: =IF(CH53="Θ", 9, IF(CH53="Ο", 3, IF(CH53="▲", 1, "0"))) -> 0 | CN71: =IF(CN53="Θ", 9, IF(CN53="Ο", 3, IF(CN53="▲", 1, "0"))) -> 0
D72: =IF($D54<>"",$D54,0) -> 0 | H72: =IF(H54="Θ", 9, IF(H54="Ο", 3, IF(H54="▲", 1, "0"))) -> 0 | N72: =IF(N54="Θ", 9, IF(N54="Ο", 3, IF(N54="▲", 1, "0"))) -> 0 | T72: =IF(T54="Θ", 9, IF(T54="Ο", 3, IF(T54="▲", 1, "0"))) -> 0 | Z72: =IF(Z54="Θ", 9, IF(Z54="Ο", 3, IF(Z54="▲", 1, "0"))) -> 0 | AF72: =IF(AF54="Θ", 9, IF(AF54="Ο", 3, IF(AF54="▲", 1, "0"))) -> 0 | AL72: =IF(AL54="Θ", 9, IF(AL54="Ο", 3, IF(AL54="▲", 1, "0"))) -> 0 | AR72: =IF(AR54="Θ", 9, IF(AR54="Ο", 3, IF(AR54="▲", 1, "0"))) -> 0 | AX72: =IF(AX54="Θ", 9, IF(AX54="Ο", 3, IF(AX54="▲", 1, "0"))) -> 0 | BD72: =IF(BD54="Θ", 9, IF(BD54="Ο", 3, IF(BD54="▲", 1, "0"))) -> 0 | BJ72: =IF(BJ54="Θ", 9, IF(BJ54="Ο", 3, IF(BJ54="▲", 1, "0"))) -> 0 | BP72: =IF(BP54="Θ", 9, IF(BP54="Ο", 3, IF(BP54="▲", 1, "0"))) -> 0 | BV72: =IF(BV54="Θ", 9, IF(BV54="Ο", 3, IF(BV54="▲", 1, "0"))) -> 0 | CB72: =IF(CB54="Θ", 9, IF(CB54="Ο", 3, IF(CB54="▲", 1, "0"))) -> 0 | CH72: =IF(CH54="Θ", 9, IF(CH54="Ο", 3, IF(CH54="▲", 1, "0"))) -> 0 | CN72: =IF(CN54="Θ", 9, IF(CN54="Ο", 3, IF(CN54="▲", 1, "0"))) -> 0
D73: =IF($D55<>"",$D55,0) -> 0 | H73: =IF(H55="Θ", 9, IF(H55="Ο", 3, IF(H55="▲", 1, "0"))) -> 0 | N73: =IF(N55="Θ", 9, IF(N55="Ο", 3, IF(N55="▲", 1, "0"))) -> 0 | T73: =IF(T55="Θ", 9, IF(T55="Ο", 3, IF(T55="▲", 1, "0"))) -> 0 | Z73: =IF(Z55="Θ", 9, IF(Z55="Ο", 3, IF(Z55="▲", 1, "0"))) -> 0 | AF73: =IF(AF55="Θ", 9, IF(AF55="Ο", 3, IF(AF55="▲", 1, "0"))) -> 0 | AL73: =IF(AL55="Θ", 9, IF(AL55="Ο", 3, IF(AL55="▲", 1, "0"))) -> 0 | AR73: =IF(AR55="Θ", 9, IF(AR55="Ο", 3, IF(AR55="▲", 1, "0"))) -> 0 | AX73: =IF(AX55="Θ", 9, IF(AX55="Ο", 3, IF(AX55="▲", 1, "0"))) -> 0 | BD73: =IF(BD55="Θ", 9, IF(BD55="Ο", 3, IF(BD55="▲", 1, "0"))) -> 0 | BJ73: =IF(BJ55="Θ", 9, IF(BJ55="Ο", 3, IF(BJ55="▲", 1, "0"))) -> 0 | BP73: =IF(BP55="Θ", 9, IF(BP55="Ο", 3, IF(BP55="▲", 1, "0"))) -> 0 | BV73: =IF(BV55="Θ", 9, IF(BV55="Ο", 3, IF(BV55="▲", 1, "0"))) -> 0 | CB73: =IF(CB55="Θ", 9, IF(CB55="Ο", 3, IF(CB55="▲", 1, "0"))) -> 0 | CH73: =IF(CH55="Θ", 9, IF(CH55="Ο", 3, IF(CH55="▲", 1, "0"))) -> 0 | CN73: =IF(CN55="Θ", 9, IF(CN55="Ο", 3, IF(CN55="▲", 1, "0"))) -> 0
D74: =IF($D56<>"",$D56,0) -> 0 | H74: =IF(H56="Θ", 9, IF(H56="Ο", 3, IF(H56="▲", 1, "0"))) -> 0 | N74: =IF(N56="Θ", 9, IF(N56="Ο", 3, IF(N56="▲", 1, "0"))) -> 0 | T74: =IF(T56="Θ", 9, IF(T56="Ο", 3, IF(T56="▲", 1, "0"))) -> 0 | Z74: =IF(Z56="Θ", 9, IF(Z56="Ο", 3, IF(Z56="▲", 1, "0"))) -> 0 | AF74: =IF(AF56="Θ", 9, IF(AF56="Ο", 3, IF(AF56="▲", 1, "0"))) -> 0 | AL74: =IF(AL56="Θ", 9, IF(AL56="Ο", 3, IF(AL56="▲", 1, "0"))) -> 0 | AR74: =IF(AR56="Θ", 9, IF(AR56="Ο", 3, IF(AR56="▲", 1, "0"))) -> 0 | AX74: =IF(AX56="Θ", 9, IF(AX56="Ο", 3, IF(AX56="▲", 1, "0"))) -> 0 | BD74: =IF(BD56="Θ", 9, IF(BD56="Ο", 3, IF(BD56="▲", 1, "0"))) -> 0 | BJ74: =IF(BJ56="Θ", 9, IF(BJ56="Ο", 3, IF(BJ56="▲", 1, "0"))) -> 0 | BP74: =IF(BP56="Θ", 9, IF(BP56="Ο", 3, IF(BP56="▲", 1, "0"))) -> 0 | BV74: =IF(BV56="Θ", 9, IF(BV56="Ο", 3, IF(BV56="▲", 1, "0"))) -> 0 | CB74: =IF(CB56="Θ", 9, IF(CB56="Ο", 3, IF(CB56="▲", 1, "0"))) -> 0 | CH74: =IF(CH56="Θ", 9, IF(CH56="Ο", 3, IF(CH56="▲", 1, "0"))) -> 0 | CN74: =IF(CN56="Θ", 9, IF(CN56="Ο", 3, IF(CN56="▲", 1, "0"))) -> 0
D75: =IF($D57<>"",$D57,0) -> 0 | H75: =IF(H57="Θ", 9, IF(H57="Ο", 3, IF(H57="▲", 1, "0"))) -> 0 | N75: =IF(N57="Θ", 9, IF(N57="Ο", 3, IF(N57="▲", 1, "0"))) -> 0 | T75: =IF(T57="Θ", 9, IF(T57="Ο", 3, IF(T57="▲", 1, "0"))) -> 0 | Z75: =IF(Z57="Θ", 9, IF(Z57="Ο", 3, IF(Z57="▲", 1, "0"))) -> 0 | AF75: =IF(AF57="Θ", 9, IF(AF57="Ο", 3, IF(AF57="▲", 1, "0"))) -> 0 | AL75: =IF(AL57="Θ", 9, IF(AL57="Ο", 3, IF(AL57="▲", 1, "0"))) -> 0 | AR75: =IF(AR57="Θ", 9, IF(AR57="Ο", 3, IF(AR57="▲", 1, "0"))) -> 0 | AX75: =IF(AX57="Θ", 9, IF(AX57="Ο", 3, IF(AX57="▲", 1, "0"))) -> 0 | BD75: =IF(BD57="Θ", 9, IF(BD57="Ο", 3, IF(BD57="▲", 1, "0"))) -> 0 | BJ75: =IF(BJ57="Θ", 9, IF(BJ57="Ο", 3, IF(BJ57="▲", 1, "0"))) -> 0 | BP75: =IF(BP57="Θ", 9, IF(BP57="Ο", 3, IF(BP57="▲", 1, "0"))) -> 0 | BV75: =IF(BV57="Θ", 9, IF(BV57="Ο", 3, IF(BV57="▲", 1, "0"))) -> 0 | CB75: =IF(CB57="Θ", 9, IF(CB57="Ο", 3, IF(CB57="▲", 1, "0"))) -> 0 | CH75: =IF(CH57="Θ", 9, IF(CH57="Ο", 3, IF(CH57="▲", 1, "0"))) -> 0 | CN75: =IF(CN57="Θ", 9, IF(CN57="Ο", 3, IF(CN57="▲", 1, "0"))) -> 0
D76: =IF($D58<>"",$D58,0) -> 0 | H76: =IF(H58="Θ", 9, IF(H58="Ο", 3, IF(H58="▲", 1, "0"))) -> 0 | N76: =IF(N58="Θ", 9, IF(N58="Ο", 3, IF(N58="▲", 1, "0"))) -> 0 | T76: =IF(T58="Θ", 9, IF(T58="Ο", 3, IF(T58="▲", 1, "0"))) -> 0 | Z76: =IF(Z58="Θ", 9, IF(Z58="Ο", 3, IF(Z58="▲", 1, "0"))) -> 0 | AF76: =IF(AF58="Θ", 9, IF(AF58="Ο", 3, IF(AF58="▲", 1, "0"))) -> 0 | AL76: =IF(AL58="Θ", 9, IF(AL58="Ο", 3, IF(AL58="▲", 1, "0"))) -> 0 | AR76: =IF(AR58="Θ", 9, IF(AR58="Ο", 3, IF(AR58="▲", 1, "0"))) -> 0 | AX76: =IF(AX58="Θ", 9, IF(AX58="Ο", 3, IF(AX58="▲", 1, "0"))) -> 0 | BD76: =IF(BD58="Θ", 9, IF(BD58="Ο", 3, IF(BD58="▲", 1, "0"))) -> 0 | BJ76: =IF(BJ58="Θ", 9, IF(BJ58="Ο", 3, IF(BJ58="▲", 1, "0"))) -> 0 | BP76: =IF(BP58="Θ", 9, IF(BP58="Ο", 3, IF(BP58="▲", 1, "0"))) -> 0 | BV76: =IF(BV58="Θ", 9, IF(BV58="Ο", 3, IF(BV58="▲", 1, "0"))) -> 0 | CB76: =IF(CB58="Θ", 9, IF(CB58="Ο", 3, IF(CB58="▲", 1, "0"))) -> 0 | CH76: =IF(CH58="Θ", 9, IF(CH58="Ο", 3, IF(CH58="▲", 1, "0"))) -> 0 | CN76: =IF(CN58="Θ", 9, IF(CN58="Ο", 3, IF(CN58="▲", 1, "0"))) -> 0
D77: =IF($D59<>"",$D59,0) -> 0 | H77: =IF(H59="Θ", 9, IF(H59="Ο", 3, IF(H59="▲", 1, "0"))) -> 0 | N77: =IF(N59="Θ", 9, IF(N59="Ο", 3, IF(N59="▲", 1, "0"))) -> 0 | T77: =IF(T59="Θ", 9, IF(T59="Ο", 3, IF(T59="▲", 1, "0"))) -> 0 | Z77: =IF(Z59="Θ", 9, IF(Z59="Ο", 3, IF(Z59="▲", 1, "0"))) -> 0 | AF77: =IF(AF59="Θ", 9, IF(AF59="Ο", 3, IF(AF59="▲", 1, "0"))) -> 0 | AL77: =IF(AL59="Θ", 9, IF(AL59="Ο", 3, IF(AL59="▲", 1, "0"))) -> 0 | AR77: =IF(AR59="Θ", 9, IF(AR59="Ο", 3, IF(AR59="▲", 1, "0"))) -> 0 | AX77: =IF(AX59="Θ", 9, IF(AX59="Ο", 3, IF(AX59="▲", 1, "0"))) -> 0 | BD77: =IF(BD59="Θ", 9, IF(BD59="Ο", 3, IF(BD59="▲", 1, "0"))) -> 0 | BJ77: =IF(BJ59="Θ", 9, IF(BJ59="Ο", 3, IF(BJ59="▲", 1, "0"))) -> 0 | BP77: =IF(BP59="Θ", 9, IF(BP59="Ο", 3, IF(BP59="▲", 1, "0"))) -> 0 | BV77: =IF(BV59="Θ", 9, IF(BV59="Ο", 3, IF(BV59="▲", 1, "0"))) -> 0 | CB77: =IF(CB59="Θ", 9, IF(CB59="Ο", 3, IF(CB59="▲", 1, "0"))) -> 0 | CH77: =IF(CH59="Θ", 9, IF(CH59="Ο", 3, IF(CH59="▲", 1, "0"))) -> 0 | CN77: =IF(CN59="Θ", 9, IF(CN59="Ο", 3, IF(CN59="▲", 1, "0"))) -> 0
...

Sheet Data Validation Sources
A1: Min, Max, or Target Options | B1: Relationship Between Requirements Options | C1: Correlation Options
A2: ▼ | B2: Θ | C2: ┼┼
A3: ▲ | B3: Ο | C3: ┼
A4: x | B4: ▲ | C4: ▬
C5: ▼

Sheet House of Quality 2
B2: Title: | CY2: Legend
B5: Author: | CY5: Θ | CZ5: Strong Relationship | DE5: 9
B8: Date: | CY8: Ο | CZ8: Moderate Relationship | DE8: 3
B11: Notes: | CY11: ▲ | CZ11: Weak Relationship | DE11: 1
CY14: ┼┼ | CZ14: Strong Positive Correlation
CY17: ┼ | CZ17: Positive Correlation
CY20: ▬ | CZ20: Negative Correlation
CY23: ▼ | CZ23: Strong Negative Correlation
CY26: ▼ | CZ26: Objective Is To Minimize
CY29: ▲ | CZ29: Objective Is To Maximize
CY32: x | CZ32: Objective Is To Hit Target
F47: Column # | M47: 1 | S47: 2 | Y47: 3 | AE47: 4 | AK47: 5 | AQ47: 6 | AW47: 7 | BC47: 8 | BI47: 9 | BO47: 10 | BU47: 11 | CA47: 12 | CG47: 13 | CM47: 14 | CS47: 15
F48: Direction of Improvement: Minimize (▼), Maximize (▲), or Target (x)
B49: Row # | C49: Max Relationship Value in Row | D49: Relative Weight | E49: Weight / Importance
J51: Quality Characteristics (a.k.a. "Hows")
G54: Demanded Quality (a.k.a. "Whats")
B56: 1 | C56: =MAX($M79:$CX79) -> 0 | D56: =IF(ISNUMBER($E56), ($E56/SUM($E$56:$E$70))*100, "") | E56: =IF('House of Quality 1'!$H64<>0, 'House of Quality 1'!$H64,"") | F56: =IF('House of Quality 1'!$H49<>"", 'House of Quality 1'!$H49,"")
B57: 2 | C57: =MAX($M80:$CX80) -> 0 | D57: =IF(ISNUMBER($E57), ($E57/SUM($E$56:$E$70))*100, "") | E57: =IF('House of Quality 1'!$N64<>0,'House of Quality 1'!$N64, "") | F57: =IF('House of Quality 1'!$N49<>"",'House of Quality 1'!$N49, "")
B58: 3 | C58: =MAX($M81:$CX81) -> 0 | D58: =IF(ISNUMBER($E58), ($E58/SUM($E$56:$E$70))*100, "") | E58: =IF('House of Quality 1'!$T64<>0,'House of Quality 1'!$T64,"") | F58: =IF('House of Quality 1'!$T49<>"",'House of Quality 1'!$T49,"")
B59: 4 | C59: =MAX($M82:$CX82) -> 0 | D59: =IF(ISNUMBER($E59), ($E59/SUM($E$56:$E$70))*100, "") | E59: =IF('House of Quality 1'!$Z64<>0,'House of Quality 1'!$Z64,"") | F59: =IF('House of Quality 1'!$Z49<>"",'House of Quality 1'!$Z49,"")
B60: 5 | C60: =MAX($M83:$CX83) -> 0 | D60: =IF(ISNUMBER($E60), ($E60/SUM($E$56:$E$70))*100, "") | E60: =IF('House of Quality 1'!$AF64<>0,'House of Quality 1'!$AF64,"") | F60: =IF('House of Quality 1'!$AF49<>"",'House of Quality 1'!$AF49,"")
B61: 6 | C61: =MAX($M84:$CX84) -> 0 | D61: =IF(ISNUMBER($E61), ($E61/SUM($E$56:$E$70))*100, "") | E61: =IF('House of Quality 1'!$AL64<>0,'House of Quality 1'!$AL64,"") | F61: =IF('House of Quality 1'!$AL49<>"",'House of Quality 1'!$AL49,"")
B62: 7 | C62: =MAX($M85:$CX85) -> 0 | D62: =IF(ISNUMBER($E62), ($E62/SUM($E$56:$E$70))*100, "") | E62: =IF('House of Quality 1'!$AR64<>0,'House of Quality 1'!$AR64,"") | F62: =IF('House of Quality 1'!$AR49<>"",'House of Quality 1'!$AR49,"")
B63: 8 | C63: =MAX($M86:$CX86) -> 0 | D63: =IF(ISNUMBER($E63), ($E63/SUM($E$56:$E$70))*100, "") | E63: =IF('House of Quality 1'!$AX64<>0,'House of Quality 1'!$AX64,"") | F63: =IF('House of Quality 1'!$AX49<>"",'House of Quality 1'!$AX49,"")
B64: 9 | C64: =MAX($M87:$CX87) -> 0 | D64: =IF(ISNUMBER($E64), ($E64/SUM($E$56:$E$70))*100, "") | E64: =IF('House of Quality 1'!$BD64<>0,'House of Quality 1'!$BD64,"") | F64: =IF('House of Quality 1'!$BD49<>"",'House of Quality 1'!$BD49,"")
B65: 10 | C65: =MAX($M88:$CX88) -> 0 | D65: =IF(ISNUMBER($E65), ($E65/SUM($E$56:$E$70))*100, "") | E65: =IF('House of Quality 1'!$BJ64<>0,'House of Quality 1'!$BJ64,"") | F65: =IF('House of Quality 1'!$BJ49<>"",'House of Quality 1'!$BJ49,"")
B66: 11 | C66: =MAX($M89:$CX89) -> 0 | D66: =IF(ISNUMBER($E66), ($E66/SUM($E$56:$E$70))*100, "") | E66: =IF('House of Quality 1'!$BP64<>0,'House of Quality 1'!$BP64,"") | F66: =IF('House of Quality 1'!$BP49<>"",'House of Quality 1'!$BP49,"")
B67: 12 | C67: =MAX($M90:$CX90) -> 0 | D67: =IF(ISNUMBER($E67), ($E67/SUM($E$56:$E$70))*100, "") | E67: =IF('House of Quality 1'!$BV64<>0,'House of Quality 1'!$BV64,"") | F67: =IF('House of Quality 1'!$BV49<>"",'House of Quality 1'!$BV49,"")
B68: 13 | C68: =MAX($M91:$CX91) -> 0 | D68: =IF(ISNUMBER($E68), ($E68/SUM($E$56:$E$70))*100, "") | E68: =IF('House of Quality 1'!$CB64<>0,'House of Quality 1'!$CB64,"") | F68: =IF('House of Quality 1'!$CB49<>"",'House of Quality 1'!$CB49,"")
B69: 14 | C69: =MAX($M92:$CX92) -> 0 | D69: =IF(ISNUMBER($E69), ($E69/SUM($E$56:$E$70))*100, "") | E69: =IF('House of Quality 1'!$CH64<>0,'House of Quality 1'!$CH64,"") | F69: =IF('House of Quality 1'!$CH49<>"",'House of Quality 1'!$CH49,"")
B70: 15 | C70: =MAX($M93:$CX93) -> 0 | D70: =IF(ISNUMBER($E70), ($E70/SUM($E$56:$E$70))*100, "") | E70: =IF('House of Quality 1'!$CN64<>0,'House of Quality 1'!$CN64,"") | F70: =IF('House of Quality 1'!$CN49<>"",'House of Quality 1'!$CN49,"")
F71: Target or Limit Value
F72: Difficulty (0=Easy to Accomplish, 10=Extremely Difficult)
F73: Max Relationship Value in Column | M73: =MAX(M79:R93) -> 0 | S73: =MAX(S79:X93) -> 0 | Y73: =MAX(Y79:AD93) -> 0 | AE73: =MAX(AE79:AJ93) -> 0 | AK73: =MAX(AK79:AP93) -> 0 | AQ73: =MAX(AQ79:AV93) -> 0 | AW73: =MAX(AW79:BB93) -> 0 | BC73: =MAX(BC79:BH93) -> 0 | BI73: =MAX(BI79:BN93) -> 0 | BO73: =MAX(BO79:BT93) -> 0 | BU73: =MAX(BU79:BZ93) -> 0 | CA73: =MAX(CA79:CF93) -> 0 | CG73: =MAX(CG79:CL93) -> 0 | CM73: =MAX(CM79:CR93) -> 0 | CS73: =MAX(CS79:CX93) -> 0
F74: Weight / Importance | M74: =SUM($D79*M79,$D80*M80,$D81*M81,$D82*M82,$D83*M83,$D84*M84,$D85*M85,$D86*M86,$D87*M87,$D88*M88,$D89*M89,$D90*M90,$D91*M91,$D92*M92,$D93*M93) -> 0 | S74: =SUM($D79*S79,$D80*S80,$D81*S81,$D82*S82,$D83*S83,$D84*S84,$D85*S85,$D86*S86,$D87*S87,$D88*S88,$D89*S89,$D90*S90,$D91*S91,$D92*S92,$D93*S93) -> 0 | Y74: =SUM($D79*Y79,$D80*Y80,$D81*Y81,$D82*Y82,$D83*Y83,$D84*Y84,$D85*Y85,$D86*Y86,$D87*Y87,$D88*Y88,$D89*Y89,$D90*Y90,$D91*Y91,$D92*Y92,$D93*Y93) -> 0 | AE74: =SUM($D79*AE79,$D80*AE80,$D81*AE81,$D82*AE82,$D83*AE83,$D84*AE84,$D85*AE85,$D86*AE86,$D87*AE87,$D88*AE88,$D89*AE89,$D90*AE90,$D91*AE91,$D92*AE92,$D93*AE93) -> 0 | AK74: =SUM($D79*AK79,$D80*AK80,$D81*AK81,$D82*AK82,$D83*AK83,$D84*AK84,$D85*AK85,$D86*AK86,$D87*AK87,$D88*AK88,$D89*AK89,$D90*AK90,$D91*AK91,$D92*AK92,$D93*AK93) -> 0 | AQ74: =SUM($D79*AQ79,$D80*AQ80,$D81*AQ81,$D82*AQ82,$D83*AQ83,$D84*AQ84,$D85*AQ85,$D86*AQ86,$D87*AQ87,$D88*AQ88,$D89*AQ89,$D90*AQ90,$D91*AQ91,$D92*AQ92,$D93*AQ93) -> 0 | AW74: =SUM($D79*AW79,$D80*AW80,$D81*AW81,$D82*AW82,$D83*AW83,$D84*AW84,$D85*AW85,$D86*AW86,$D87*AW87,$D88*AW88,$D89*AW89,$D90*AW90,$D91*AW91,$D92*AW92,$D93*AW93) -> 0 | BC74: =SUM($D79*BC79,$D80*BC80,$D81*BC81,$D82*BC82,$D83*BC83,$D84*BC84,$D85*BC85,$D86*BC86,$D87*BC87,$D88*BC88,$D89*BC89,$D90*BC90,$D91*BC91,$D92*BC92,$D93*BC93) -> 0 | BI74: =SUM($D79*BI79,$D80*BI80,$D81*BI81,$D82*BI82,$D83*BI83,$D84*BI84,$D85*BI85,$D86*BI86,$D87*BI87,$D88*BI88,$D89*BI89,$D90*BI90,$D91*BI91,$D92*BI92,$D93*BI93) -> 0 | BO74: =SUM($D79*BO79,$D80*BO80,$D81*BO81,$D82*BO82,$D83*BO83,$D84*BO84,$D85*BO85,$D86*BO86,$D87*BO87,$D88*BO88,$D89*BO89,$D90*BO90,$D91*BO91,$D92*BO92,$D93*BO93) -> 0 | BU74: =SUM($D79*BU79,$D80*BU80,$D81*BU81,$D82*BU82,$D83*BU83,$D84*BU84,$D85*BU85,$D86*BU86,$D87*BU87,$D88*BU88,$D89*BU89,$D90*BU90,$D91*BU91,$D92*BU92,$D93*BU93) -> 0 | CA74: =SUM($D79*CA79,$D80*CA80,$D81*CA81,$D82*CA82,$D83*CA83,$D84*CA84,$D85*CA85,$D86*CA86,$D87*CA87,$D88*CA88,$D89*CA89,$D90*CA90,$D91*CA91,$D92*CA92,$D93*CA93) -> 0 | CG74: =SUM($D79*CG79,$D80*CG80,$D81*CG81,$D82*CG82,$D83*CG83,$D84*CG84,$D85*CG85,$D86*CG86,$D87*CG87,$D88*CG88,$D89*CG89,$D90*CG90,$D91*CG91,$D92*CG92,$D93*CG93) -> 0 | CM74: =SUM($D79*CM79,$D80*CM80,$D81*CM81,$D82*CM82,$D83*CM83,$D84*CM84,$D85*CM85,$D86*CM86,$D87*CM87,$D88*CM88,$D89*CM89,$D90*CM90,$D91*CM91,$D92*CM92,$D93*CM93) -> 0 | CS74: =SUM($D79*CS79,$D80*CS80,$D81*CS81,$D82*CS82,$D83*CS83,$D84*CS84,$D85*CS85,$D86*CS86,$D87*CS87,$D88*CS88,$D89*CS89,$D90*CS90,$D91*CS91,$D92*CS92,$D93*CS93) -> 0
F75: Relative Weight | M75: =IF(M$74>0,(M$74/SUM($74:$74))*100, "") | S75: =IF(S$74>0,(S$74/SUM($74:$74))*100, "") | Y75: =IF(Y$74>0,(Y$74/SUM($74:$74))*100, "") | AE75: =IF(AE$74>0,(AE$74/SUM($74:$74))*100, "") | AK75: =IF(AK$74>0,(AK$74/SUM($74:$74))*100, "") | AQ75: =IF(AQ$74>0,(AQ$74/SUM($74:$74))*100, "") | AW75: =IF(AW$74>0,(AW$74/SUM($74:$74))*100, "") | BC75: =IF(BC$74>0,(BC$74/SUM($74:$74))*100, "") | BI75: =IF(BI$74>0,(BI$74/SUM($74:$74))*100, "") | BO75: =IF(BO$74>0,(BO$74/SUM($74:$74))*100, "") | BU75: =IF(BU$74>0,(BU$74/SUM($74:$74))*100, "") | CA75: =IF(CA$74>0,(CA$74/SUM($74:$74))*100, "") | CG75: =IF(CG$74>0,(CG$74/SUM($74:$74))*100, "") | CM75: =IF(CM$74>0,(CM$74/SUM($74:$74))*100, "") | CS75: =IF(CS$74>0,(CS$74/SUM($74:$74))*100, "") | CY75: Powered by QFD Online (http://www.QFDOnline.com)
D78: Numeric Values for Relationship Matrix Calculations
D79: =IF($D56<>"",$D56,0) -> 0 | M79: =IF(M56="Θ", 9, IF(M56="Ο", 3, IF(M56="▲", 1, "0"))) -> 0 | S79: =IF(S56="Θ", 9, IF(S56="Ο", 3, IF(S56="▲", 1, "0"))) -> 0 | Y79: =IF(Y56="Θ", 9, IF(Y56="Ο", 3, IF(Y56="▲", 1, "0"))) -> 0 | AE79: =IF(AE56="Θ", 9, IF(AE56="Ο", 3, IF(AE56="▲", 1, "0"))) -> 0 | AK79: =IF(AK56="Θ", 9, IF(AK56="Ο", 3, IF(AK56="▲", 1, "0"))) -> 0 | AQ79: =IF(AQ56="Θ", 9, IF(AQ56="Ο", 3, IF(AQ56="▲", 1, "0"))) -> 0 | AW79: =IF(AW56="Θ", 9, IF(AW56="Ο", 3, IF(AW56="▲", 1, "0"))) -> 0 | BC79: =IF(BC56="Θ", 9, IF(BC56="Ο", 3, IF(BC56="▲", 1, "0"))) -> 0 | BI79: =IF(BI56="Θ", 9, IF(BI56="Ο", 3, IF(BI56="▲", 1, "0"))) -> 0 | BO79: =IF(BO56="Θ", 9, IF(BO56="Ο", 3, IF(BO56="▲", 1, "0"))) -> 0 | BU79: =IF(BU56="Θ", 9, IF(BU56="Ο", 3, IF(BU56="▲", 1, "0"))) -> 0 | CA79: =IF(CA56="Θ", 9, IF(CA56="Ο", 3, IF(CA56="▲", 1, "0"))) -> 0 | CG79: =IF(CG56="Θ", 9, IF(CG56="Ο", 3, IF(CG56="▲", 1, "0"))) -> 0 | CM79: =IF(CM56="Θ", 9, IF(CM56="Ο", 3, IF(CM56="▲", 1, "0"))) -> 0 | CS79: =IF(CS56="Θ", 9, IF(CS56="Ο", 3, IF(CS56="▲", 1, "0"))) -> 0
D80: =IF($D57<>"",$D57,0) -> 0 | M80: =IF(M57="Θ", 9, IF(M57="Ο", 3, IF(M57="▲", 1, "0"))) -> 0 | S80: =IF(S57="Θ", 9, IF(S57="Ο", 3, IF(S57="▲", 1, "0"))) -> 0 | Y80: =IF(Y57="Θ", 9, IF(Y57="Ο", 3, IF(Y57="▲", 1, "0"))) -> 0 | AE80: =IF(AE57="Θ", 9, IF(AE57="Ο", 3, IF(AE57="▲", 1, "0"))) -> 0 | AK80: =IF(AK57="Θ", 9, IF(AK57="Ο", 3, IF(AK57="▲", 1, "0"))) -> 0 | AQ80: =IF(AQ57="Θ", 9, IF(AQ57="Ο", 3, IF(AQ57="▲", 1, "0"))) -> 0 | AW80: =IF(AW57="Θ", 9, IF(AW57="Ο", 3, IF(AW57="▲", 1, "0"))) -> 0 | BC80: =IF(BC57="Θ", 9, IF(BC57="Ο", 3, IF(BC57="▲", 1, "0"))) -> 0 | BI80: =IF(BI57="Θ", 9, IF(BI57="Ο", 3, IF(BI57="▲", 1, "0"))) -> 0 | BO80: =IF(BO57="Θ", 9, IF(BO57="Ο", 3, IF(BO57="▲", 1, "0"))) -> 0 | BU80: =IF(BU57="Θ", 9, IF(BU57="Ο", 3, IF(BU57="▲", 1, "0"))) -> 0 | CA80: =IF(CA57="Θ", 9, IF(CA57="Ο", 3, IF(CA57="▲", 1, "0"))) -> 0 | CG80: =IF(CG57="Θ", 9, IF(CG57="Ο", 3, IF(CG57="▲", 1, "0"))) -> 0 | CM80: =IF(CM57="Θ", 9, IF(CM57="Ο", 3, IF(CM57="▲", 1, "0"))) -> 0 | CS80: =IF(CS57="Θ", 9, IF(CS57="Ο", 3, IF(CS57="▲", 1, "0"))) -> 0
D81: =IF($D58<>"",$D58,0) -> 0 | M81: =IF(M58="Θ", 9, IF(M58="Ο", 3, IF(M58="▲", 1, "0"))) -> 0 | S81: =IF(S58="Θ", 9, IF(S58="Ο", 3, IF(S58="▲", 1, "0"))) -> 0 | Y81: =IF(Y58="Θ", 9, IF(Y58="Ο", 3, IF(Y58="▲", 1, "0"))) -> 0 | AE81: =IF(AE58="Θ", 9, IF(AE58="Ο", 3, IF(AE58="▲", 1, "0"))) -> 0 | AK81: =IF(AK58="Θ", 9, IF(AK58="Ο", 3, IF(AK58="▲", 1, "0"))) -> 0 | AQ81: =IF(AQ58="Θ", 9, IF(AQ58="Ο", 3, IF(AQ58="▲", 1, "0"))) -> 0 | AW81: =IF(AW58="Θ", 9, IF(AW58="Ο", 3, IF(AW58="▲", 1, "0"))) -> 0 | BC81: =IF(BC58="Θ", 9, IF(BC58="Ο", 3, IF(BC58="▲", 1, "0"))) -> 0 | BI81: =IF(BI58="Θ", 9, IF(BI58="Ο", 3, IF(BI58="▲", 1, "0"))) -> 0 | BO81: =IF(BO58="Θ", 9, IF(BO58="Ο", 3, IF(BO58="▲", 1, "0"))) -> 0 | BU81: =IF(BU58="Θ", 9, IF(BU58="Ο", 3, IF(BU58="▲", 1, "0"))) -> 0 | CA81: =IF(CA58="Θ", 9, IF(CA58="Ο", 3, IF(CA58="▲", 1, "0"))) -> 0 | CG81: =IF(CG58="Θ", 9, IF(CG58="Ο", 3, IF(CG58="▲", 1, "0"))) -> 0 | CM81: =IF(CM58="Θ", 9, IF(CM58="Ο", 3, IF(CM58="▲", 1, "0"))) -> 0 | CS81: =IF(CS58="Θ", 9, IF(CS58="Ο", 3, IF(CS58="▲", 1, "0"))) -> 0
...

Sheet House of Quality 3
B2: Title: | CY2: Legend
B5: Author: | CY5: Θ | CZ5: Strong Relationship | DE5: 9
B8: Date: | CY8: Ο | CZ8: Moderate Relationship | DE8: 3
B11: Notes: | CY11: ▲ | CZ11: Weak Relationship | DE11: 1
CY14: ┼┼ | CZ14: Strong Positive Correlation
CY17: ┼ | CZ17: Positive Correlation
CY20: ▬ | CZ20: Negative Correlation
CY23: ▼ | CZ23: Strong Negative Correlation
CY26: ▼ | CZ26: Objective Is To Minimize
CY29: ▲ | CZ29: Objective Is To Maximize
CY32: x | CZ32: Objective Is To Hit Target
F47: Column # | M47: 1 | S47: 2 | Y47: 3 | AE47: 4 | AK47: 5 | AQ47: 6 | AW47: 7 | BC47: 8 | BI47: 9 | BO47: 10 | BU47: 11 | CA47: 12 | CG47: 13 | CM47: 14 | CS47: 15
F48: Direction of Improvement: Minimize (▼), Maximize (▲), or Target (x)
B49: Row # | C49: Max Relationship Value in Row | D49: Relative Weight | E49: Weight / Importance
J51: Quality Characteristics (a.k.a. "Hows")
G54: Demanded Quality (a.k.a. "Whats")
B56: 1 | C56: =MAX($M79:$CX79) -> 0 | D56: =IF(ISNUMBER($E56), ($E56/SUM($E$56:$E$70))*100, "") | E56: =IF('House of Quality 2'!$M$74<>0, 'House of Quality 2'!$M$74,"") | F56: =IF('House of Quality 2'!$M$49<>"", 'House of Quality 2'!$M$49,"")
B57: 2 | C57: =MAX($M80:$CX80) -> 0 | D57: =IF(ISNUMBER($E57), ($E57/SUM($E$56:$E$70))*100, "") | E57: =IF('House of Quality 2'!$S$74<>0, 'House of Quality 2'!$S$74,"") | F57: =IF('House of Quality 2'!$S$49<>"", 'House of Quality 2'!$S$49,"")
B58: 3 | C58: =MAX($M81:$CX81) -> 0 | D58: =IF(ISNUMBER($E58), ($E58/SUM($E$56:$E$70))*100, "") | E58: =IF('House of Quality 2'!$Y$74<>0, 'House of Quality 2'!$Y$74,"") | F58: =IF('House of Quality 2'!$Y$49<>"", 'House of Quality 2'!$Y$49,"")
B59: 4 | C59: =MAX($M82:$CX82) -> 0 | D59: =IF(ISNUMBER($E59), ($E59/SUM($E$56:$E$70))*100, "") | E59: =IF('House of Quality 2'!$AE$74<>0, 'House of Quality 2'!$AE$74,"") | F59: =IF('House of Quality 2'!$AE$49<>"", 'House of Quality 2'!$AE$49,"")
B60: 5 | C60: =MAX($M83:$CX83) -> 0 | D60: =IF(ISNUMBER($E60), ($E60/SUM($E$56:$E$70))*100, "") | E60: =IF('House of Quality 2'!$AK$74<>0, 'House of Quality 2'!$AK$74,"") | F60: =IF('House of Quality 2'!$AK$49<>"", 'House of Quality 2'!$AK$49,"")
B61: 6 | C61: =MAX($M84:$CX84) -> 0 | D61: =IF(ISNUMBER($E61), ($E61/SUM($E$56:$E$70))*100, "") | E61: =IF('House of Quality 2'!$AQ$74<>0, 'House of Quality 2'!$AQ$74,"") | F61: =IF('House of Quality 2'!$AQ$49<>"", 'House of Quality 2'!$AQ$49,"")
B62: 7 | C62: =MAX($M85:$CX85) -> 0 | D62: =IF(ISNUMBER($E62), ($E62/SUM($E$56:$E$70))*100, "") | E62: =IF('House of Quality 2'!$AW$74<>0, 'House of Quality 2'!$AW$74,"") | F62: =IF('House of Quality 2'!$AW$49<>"", 'House of Quality 2'!$AW$49,"")
B63: 8 | C63: =MAX($M86:$CX86) -> 0 | D63: =IF(ISNUMBER($E63), ($E63/SUM($E$56:$E$70))*100, "") | E63: =IF('House of Quality 2'!$BC$74<>0, 'House of Quality 2'!$BC$74,"") | F63: =IF('House of Quality 2'!$BC$49<>"", 'House of Quality 2'!$BC$49,"")
B64: 9 | C64: =MAX($M87:$CX87) -> 0 | D64: =IF(ISNUMBER($E64), ($E64/SUM($E$56:$E$70))*100, "") | E64: =IF('House of Quality 2'!$BI$74<>0, 'House of Quality 2'!$BI$74,"") | F64: =IF('House of Quality 2'!$BI$49<>"", 'House of Quality 2'!$BI$49,"")
B65: 10 | C65: =MAX($M88:$CX88) -> 0 | D65: =IF(ISNUMBER($E65), ($E65/SUM($E$56:$E$70))*100, "") | E65: =IF('House of Quality 2'!$BO$74<>0, 'House of Quality 2'!$BO$74,"") | F65: =IF('House of Quality 2'!$BO$49<>"", 'House of Quality 2'!$BO$49,"")
B66: 11 | C66: =MAX($M89:$CX89) -> 0 | D66: =IF(ISNUMBER($E66), ($E66/SUM($E$56:$E$70))*100, "") | E66: =IF('House of Quality 2'!$BU$74<>0, 'House of Quality 2'!$BU$74,"") | F66: =IF('House of Quality 2'!$BU$49<>"", 'House of Quality 2'!$BU$49,"")
B67: 12 | C67: =MAX($M90:$CX90) -> 0 | D67: =IF(ISNUMBER($E67), ($E67/SUM($E$56:$E$70))*100, "") | E67: =IF('House of Quality 2'!$CA$74<>0, 'House of Quality 2'!$CA$74,"") | F67: =IF('House of Quality 2'!$CA$49<>"", 'House of Quality 2'!$CA$49,"")
B68: 13 | C68: =MAX($M91:$CX91) -> 0 | D68: =IF(ISNUMBER($E68), ($E68/SUM($E$56:$E$70))*100, "") | E68: =IF('House of Quality 2'!$CG$74<>0, 'House of Quality 2'!$CG$74,"") | F68: =IF('House of Quality 2'!$CG$49<>"", 'House of Quality 2'!$CG$49,"")
B69: 14 | C69: =MAX($M92:$CX92) -> 0 | D69: =IF(ISNUMBER($E69), ($E69/SUM($E$56:$E$70))*100, "") | E69: =IF('House of Quality 2'!$CM$74<>0, 'House of Quality 2'!$CM$74,"") | F69: =IF('House of Quality 2'!$CM$49<>"", 'House of Quality 2'!$CM$49,"")
B70: 15 | C70: =MAX($M93:$CX93) -> 0 | D70: =IF(ISNUMBER($E70), ($E70/SUM($E$56:$E$70))*100, "") | E70: =IF('House of Quality 2'!$CS$74<>0, 'House of Quality 2'!$CS$74,"") | F70: =IF('House of Quality 2'!$CS$49<>"", 'House of Quality 2'!$CS$49,"")
F71: Target or Limit Value
F72: Difficulty (0=Easy to Accomplish, 10=Extremely Difficult)
F73: Max Relationship Value in Column | M73: =MAX(M79:R93) -> 0 | S73: =MAX(S79:X93) -> 0 | Y73: =MAX(Y79:AD93) -> 0 | AE73: =MAX(AE79:AJ93) -> 0 | AK73: =MAX(AK79:AP93) -> 0 | AQ73: =MAX(AQ79:AV93) -> 0 | AW73: =MAX(AW79:BB93) -> 0 | BC73: =MAX(BC79:BH93) -> 0 | BI73: =MAX(BI79:BN93) -> 0 | BO73: =MAX(BO79:BT93) -> 0 | BU73: =MAX(BU79:BZ93) -> 0 | CA73: =MAX(CA79:CF93) -> 0 | CG73: =MAX(CG79:CL93) -> 0 | CM73: =MAX(CM79:CR93) -> 0 | CS73: =MAX(CS79:CX93) -> 0
F74: Weight / Importance | M74: =SUM($D79*M79,$D80*M80,$D81*M81,$D82*M82,$D83*M83,$D84*M84,$D85*M85,$D86*M86,$D87*M87,$D88*M88,$D89*M89,$D90*M90,$D91*M91,$D92*M92,$D93*M93) -> 0 | S74: =SUM($D79*S79,$D80*S80,$D81*S81,$D82*S82,$D83*S83,$D84*S84,$D85*S85,$D86*S86,$D87*S87,$D88*S88,$D89*S89,$D90*S90,$D91*S91,$D92*S92,$D93*S93) -> 0 | Y74: =SUM($D79*Y79,$D80*Y80,$D81*Y81,$D82*Y82,$D83*Y83,$D84*Y84,$D85*Y85,$D86*Y86,$D87*Y87,$D88*Y88,$D89*Y89,$D90*Y90,$D91*Y91,$D92*Y92,$D93*Y93) -> 0 | AE74: =SUM($D79*AE79,$D80*AE80,$D81*AE81,$D82*AE82,$D83*AE83,$D84*AE84,$D85*AE85,$D86*AE86,$D87*AE87,$D88*AE88,$D89*AE89,$D90*AE90,$D91*AE91,$D92*AE92,$D93*AE93) -> 0 | AK74: =SUM($D79*AK79,$D80*AK80,$D81*AK81,$D82*AK82,$D83*AK83,$D84*AK84,$D85*AK85,$D86*AK86,$D87*AK87,$D88*AK88,$D89*AK89,$D90*AK90,$D91*AK91,$D92*AK92,$D93*AK93) -> 0 | AQ74: =SUM($D79*AQ79,$D80*AQ80,$D81*AQ81,$D82*AQ82,$D83*AQ83,$D84*AQ84,$D85*AQ85,$D86*AQ86,$D87*AQ87,$D88*AQ88,$D89*AQ89,$D90*AQ90,$D91*AQ91,$D92*AQ92,$D93*AQ93) -> 0 | AW74: =SUM($D79*AW79,$D80*AW80,$D81*AW81,$D82*AW82,$D83*AW83,$D84*AW84,$D85*AW85,$D86*AW86,$D87*AW87,$D88*AW88,$D89*AW89,$D90*AW90,$D91*AW91,$D92*AW92,$D93*AW93) -> 0 | BC74: =SUM($D79*BC79,$D80*BC80,$D81*BC81,$D82*BC82,$D83*BC83,$D84*BC84,$D85*BC85,$D86*BC86,$D87*BC87,$D88*BC88,$D89*BC89,$D90*BC90,$D91*BC91,$D92*BC92,$D93*BC93) -> 0 | BI74: =SUM($D79*BI79,$D80*BI80,$D81*BI81,$D82*BI82,$D83*BI83,$D84*BI84,$D85*BI85,$D86*BI86,$D87*BI87,$D88*BI88,$D89*BI89,$D90*BI90,$D91*BI91,$D92*BI92,$D93*BI93) -> 0 | BO74: =SUM($D79*BO79,$D80*BO80,$D81*BO81,$D82*BO82,$D83*BO83,$D84*BO84,$D85*BO85,$D86*BO86,$D87*BO87,$D88*BO88,$D89*BO89,$D90*BO90,$D91*BO91,$D92*BO92,$D93*BO93) -> 0 | BU74: =SUM($D79*BU79,$D80*BU80,$D81*BU81,$D82*BU82,$D83*BU83,$D84*BU84,$D85*BU85,$D86*BU86,$D87*BU87,$D88*BU88,$D89*BU89,$D90*BU90,$D91*BU91,$D92*BU92,$D93*BU93) -> 0 | CA74: =SUM($D79*CA79,$D80*CA80,$D81*CA81,$D82*CA82,$D83*CA83,$D84*CA84,$D85*CA85,$D86*CA86,$D87*CA87,$D88*CA88,$D89*CA89,$D90*CA90,$D91*CA91,$D92*CA92,$D93*CA93) -> 0 | CG74: =SUM($D79*CG79,$D80*CG80,$D81*CG81,$D82*CG82,$D83*CG83,$D84*CG84,$D85*CG85,$D86*CG86,$D87*CG87,$D88*CG88,$D89*CG89,$D90*CG90,$D91*CG91,$D92*CG92,$D93*CG93) -> 0 | CM74: =SUM($D79*CM79,$D80*CM80,$D81*CM81,$D82*CM82,$D83*CM83,$D84*CM84,$D85*CM85,$D86*CM86,$D87*CM87,$D88*CM88,$D89*CM89,$D90*CM90,$D91*CM91,$D92*CM92,$D93*CM93) -> 0 | CS74: =SUM($D79*CS79,$D80*CS80,$D81*CS81,$D82*CS82,$D83*CS83,$D84*CS84,$D85*CS85,$D86*CS86,$D87*CS87,$D88*CS88,$D89*CS89,$D90*CS90,$D91*CS91,$D92*CS92,$D93*CS93) -> 0
F75: Relative Weight | M75: =IF(M$74>0,(M$74/SUM($74:$74))*100, "") | S75: =IF(S$74>0,(S$74/SUM($74:$74))*100, "") | Y75: =IF(Y$74>0,(Y$74/SUM($74:$74))*100, "") | AE75: =IF(AE$74>0,(AE$74/SUM($74:$74))*100, "") | AK75: =IF(AK$74>0,(AK$74/SUM($74:$74))*100, "") | AQ75: =IF(AQ$74>0,(AQ$74/SUM($74:$74))*100, "") | AW75: =IF(AW$74>0,(AW$74/SUM($74:$74))*100, "") | BC75: =IF(BC$74>0,(BC$74/SUM($74:$74))*100, "") | BI75: =IF(BI$74>0,(BI$74/SUM($74:$74))*100, "") | BO75: =IF(BO$74>0,(BO$74/SUM($74:$74))*100, "") | BU75: =IF(BU$74>0,(BU$74/SUM($74:$74))*100, "") | CA75: =IF(CA$74>0,(CA$74/SUM($74:$74))*100, "") | CG75: =IF(CG$74>0,(CG$74/SUM($74:$74))*100, "") | CM75: =IF(CM$74>0,(CM$74/SUM($74:$74))*100, "") | CS75: =IF(CS$74>0,(CS$74/SUM($74:$74))*100, "") | CY75: Powered by QFD Online (http://www.QFDOnline.com)
D78: Numeric Values for Relationship Matrix Calculations
D79: =IF($D56<>"",$D56,0) -> 0 | M79: =IF(M56="Θ", 9, IF(M56="Ο", 3, IF(M56="▲", 1, "0"))) -> 0 | S79: =IF(S56="Θ", 9, IF(S56="Ο", 3, IF(S56="▲", 1, "0"))) -> 0 | Y79: =IF(Y56="Θ", 9, IF(Y56="Ο", 3, IF(Y56="▲", 1, "0"))) -> 0 | AE79: =IF(AE56="Θ", 9, IF(AE56="Ο", 3, IF(AE56="▲", 1, "0"))) -> 0 | AK79: =IF(AK56="Θ", 9, IF(AK56="Ο", 3, IF(AK56="▲", 1, "0"))) -> 0 | AQ79: =IF(AQ56="Θ", 9, IF(AQ56="Ο", 3, IF(AQ56="▲", 1, "0"))) -> 0 | AW79: =IF(AW56="Θ", 9, IF(AW56="Ο", 3, IF(AW56="▲", 1, "0"))) -> 0 | BC79: =IF(BC56="Θ", 9, IF(BC56="Ο", 3, IF(BC56="▲", 1, "0"))) -> 0 | BI79: =IF(BI56="Θ", 9, IF(BI56="Ο", 3, IF(BI56="▲", 1, "0"))) -> 0 | BO79: =IF(BO56="Θ", 9, IF(BO56="Ο", 3, IF(BO56="▲", 1, "0"))) -> 0 | BU79: =IF(BU56="Θ", 9, IF(BU56="Ο", 3, IF(BU56="▲", 1, "0"))) -> 0 | CA79: =IF(CA56="Θ", 9, IF(CA56="Ο", 3, IF(CA56="▲", 1, "0"))) -> 0 | CG79: =IF(CG56="Θ", 9, IF(CG56="Ο", 3, IF(CG56="▲", 1, "0"))) -> 0 | CM79: =IF(CM56="Θ", 9, IF(CM56="Ο", 3, IF(CM56="▲", 1, "0"))) -> 0 | CS79: =IF(CS56="Θ", 9, IF(CS56="Ο", 3, IF(CS56="▲", 1, "0"))) -> 0
D80: =IF($D57<>"",$D57,0) -> 0 | M80: =IF(M57="Θ", 9, IF(M57="Ο", 3, IF(M57="▲", 1, "0"))) -> 0 | S80: =IF(S57="Θ", 9, IF(S57="Ο", 3, IF(S57="▲", 1, "0"))) -> 0 | Y80: =IF(Y57="Θ", 9, IF(Y57="Ο", 3, IF(Y57="▲", 1, "0"))) -> 0 | AE80: =IF(AE57="Θ", 9, IF(AE57="Ο", 3, IF(AE57="▲", 1, "0"))) -> 0 | AK80: =IF(AK57="Θ", 9, IF(AK57="Ο", 3, IF(AK57="▲", 1, "0"))) -> 0 | AQ80: =IF(AQ57="Θ", 9, IF(AQ57="Ο", 3, IF(AQ57="▲", 1, "0"))) -> 0 | AW80: =IF(AW57="Θ", 9, IF(AW57="Ο", 3, IF(AW57="▲", 1, "0"))) -> 0 | BC80: =IF(BC57="Θ", 9, IF(BC57="Ο", 3, IF(BC57="▲", 1, "0"))) -> 0 | BI80: =IF(BI57="Θ", 9, IF(BI57="Ο", 3, IF(BI57="▲", 1, "0"))) -> 0 | BO80: =IF(BO57="Θ", 9, IF(BO57="Ο", 3, IF(BO57="▲", 1, "0"))) -> 0 | BU80: =IF(BU57="Θ", 9, IF(BU57="Ο", 3, IF(BU57="▲", 1, "0"))) -> 0 | CA80: =IF(CA57="Θ", 9, IF(CA57="Ο", 3, IF(CA57="▲", 1, "0"))) -> 0 | CG80: =IF(CG57="Θ", 9, IF(CG57="Ο", 3, IF(CG57="▲", 1, "0"))) -> 0 | CM80: =IF(CM57="Θ", 9, IF(CM57="Ο", 3, IF(CM57="▲", 1, "0"))) -> 0 | CS80: =IF(CS57="Θ", 9, IF(CS57="Ο", 3, IF(CS57="▲", 1, "0"))) -> 0
D81: =IF($D58<>"",$D58,0) -> 0 | M81: =IF(M58="Θ", 9, IF(M58="Ο", 3, IF(M58="▲", 1, "0"))) -> 0 | S81: =IF(S58="Θ", 9, IF(S58="Ο", 3, IF(S58="▲", 1, "0"))) -> 0 | Y81: =IF(Y58="Θ", 9, IF(Y58="Ο", 3, IF(Y58="▲", 1, "0"))) -> 0 | AE81: =IF(AE58="Θ", 9, IF(AE58="Ο", 3, IF(AE58="▲", 1, "0"))) -> 0 | AK81: =IF(AK58="Θ", 9, IF(AK58="Ο", 3, IF(AK58="▲", 1, "0"))) -> 0 | AQ81: =IF(AQ58="Θ", 9, IF(AQ58="Ο", 3, IF(AQ58="▲", 1, "0"))) -> 0 | AW81: =IF(AW58="Θ", 9, IF(AW58="Ο", 3, IF(AW58="▲", 1, "0"))) -> 0 | BC81: =IF(BC58="Θ", 9, IF(BC58="Ο", 3, IF(BC58="▲", 1, "0"))) -> 0 | BI81: =IF(BI58="Θ", 9, IF(BI58="Ο", 3, IF(BI58="▲", 1, "0"))) -> 0 | BO81: =IF(BO58="Θ", 9, IF(BO58="Ο", 3, IF(BO58="▲", 1, "0"))) -> 0 | BU81: =IF(BU58="Θ", 9, IF(BU58="Ο", 3, IF(BU58="▲", 1, "0"))) -> 0 | CA81: =IF(CA58="Θ", 9, IF(CA58="Ο", 3, IF(CA58="▲", 1, "0"))) -> 0 | CG81: =IF(CG58="Θ", 9, IF(CG58="Ο", 3, IF(CG58="▲", 1, "0"))) -> 0 | CM81: =IF(CM58="Θ", 9, IF(CM58="Ο", 3, IF(CM58="▲", 1, "0"))) -> 0 | CS81: =IF(CS58="Θ", 9, IF(CS58="Ο", 3, IF(CS58="▲", 1, "0"))) -> 0
...

Sheet House of Quality 4
B2: Title: | CY2: Legend
B5: Author: | CY5: Θ | CZ5: Strong Relationship | DE5: 9
B8: Date: | CY8: Ο | CZ8: Moderate Relationship | DE8: 3
B11: Notes: | CY11: ▲ | CZ11: Weak Relationship | DE11: 1
CY14: ┼┼ | CZ14: Strong Positive Correlation
CY17: ┼ | CZ17: Positive Correlation
CY20: ▬ | CZ20: Negative Correlation
CY23: ▼ | CZ23: Strong Negative Correlation
CY26: ▼ | CZ26: Objective Is To Minimize
CY29: ▲ | CZ29: Objective Is To Maximize
CY32: x | CZ32: Objective Is To Hit Target
F47: Column # | M47: 1 | S47: 2 | Y47: 3 | AE47: 4 | AK47: 5 | AQ47: 6 | AW47: 7 | BC47: 8 | BI47: 9 | BO47: 10 | BU47: 11 | CA47: 12 | CG47: 13 | CM47: 14 | CS47: 15
F48: Direction of Improvement: Minimize (▼), Maximize (▲), or Target (x)
B49: Row # | C49: Max Relationship Value in Row | D49: Relative Weight | E49: Weight / Importance
J51: Quality Characteristics (a.k.a. "Hows")
G54: Demanded Quality (a.k.a. "Whats")
B56: 1 | C56: =MAX($M79:$CX79) -> 0 | D56: =IF(ISNUMBER($E56), ($E56/SUM($E$56:$E$70))*100, "") | E56: =IF('House of Quality 3'!$M$74<>0, 'House of Quality 3'!$M$74,"") | F56: =IF('House of Quality 3'!$M$49<>"", 'House of Quality 3'!$M$49,"")
B57: 2 | C57: =MAX($M80:$CX80) -> 0 | D57: =IF(ISNUMBER($E57), ($E57/SUM($E$56:$E$70))*100, "") | E57: =IF('House of Quality 3'!$S$74<>0, 'House of Quality 3'!$S$74,"") | F57: =IF('House of Quality 3'!$S$49<>"", 'House of Quality 3'!$S$49,"")
B58: 3 | C58: =MAX($M81:$CX81) -> 0 | D58: =IF(ISNUMBER($E58), ($E58/SUM($E$56:$E$70))*100, "") | E58: =IF('House of Quality 3'!$Y$74<>0, 'House of Quality 3'!$Y$74,"") | F58: =IF('House of Quality 3'!$Y$49<>"", 'House of Quality 3'!$Y$49,"")
B59: 4 | C59: =MAX($M82:$CX82) -> 0 | D59: =IF(ISNUMBER($E59), ($E59/SUM($E$56:$E$70))*100, "") | E59: =IF('House of Quality 3'!$AE$74<>0, 'House of Quality 3'!$AE$74,"") | F59: =IF('House of Quality 3'!$AE$49<>"", 'House of Quality 3'!$AE$49,"")
B60: 5 | C60: =MAX($M83:$CX83) -> 0 | D60: =IF(ISNUMBER($E60), ($E60/SUM($E$56:$E$70))*100, "") | E60: =IF('House of Quality 3'!$AK$74<>0, 'House of Quality 3'!$AK$74,"") | F60: =IF('House of Quality 3'!$AK$49<>"", 'House of Quality 3'!$AK$49,"")
B61: 6 | C61: =MAX($M84:$CX84) -> 0 | D61: =IF(ISNUMBER($E61), ($E61/SUM($E$56:$E$70))*100, "") | E61: =IF('House of Quality 3'!$AQ$74<>0, 'House of Quality 3'!$AQ$74,"") | F61: =IF('House of Quality 3'!$AQ$49<>"", 'House of Quality 3'!$AQ$49,"")
B62: 7 | C62: =MAX($M85:$CX85) -> 0 | D62: =IF(ISNUMBER($E62), ($E62/SUM($E$56:$E$70))*100, "") | E62: =IF('House of Quality 3'!$AW$74<>0, 'House of Quality 3'!$AW$74,"") | F62: =IF('House of Quality 3'!$AW$49<>"", 'House of Quality 3'!$AW$49,"")
B63: 8 | C63: =MAX($M86:$CX86) -> 0 | D63: =IF(ISNUMBER($E63), ($E63/SUM($E$56:$E$70))*100, "") | E63: =IF('House of Quality 3'!$BC$74<>0, 'House of Quality 3'!$BC$74,"") | F63: =IF('House of Quality 3'!$BC$49<>"", 'House of Quality 3'!$BC$49,"")
B64: 9 | C64: =MAX($M87:$CX87) -> 0 | D64: =IF(ISNUMBER($E64), ($E64/SUM($E$56:$E$70))*100, "") | E64: =IF('House of Quality 3'!$BI$74<>0, 'House of Quality 3'!$BI$74,"") | F64: =IF('House of Quality 3'!$BI$49<>"", 'House of Quality 3'!$BI$49,"")
B65: 10 | C65: =MAX($M88:$CX88) -> 0 | D65: =IF(ISNUMBER($E65), ($E65/SUM($E$56:$E$70))*100, "") | E65: =IF('House of Quality 3'!$BO$74<>0, 'House of Quality 3'!$BO$74,"") | F65: =IF('House of Quality 3'!$BO$49<>"", 'House of Quality 3'!$BO$49,"")
B66: 11 | C66: =MAX($M89:$CX89) -> 0 | D66: =IF(ISNUMBER($E66), ($E66/SUM($E$56:$E$70))*100, "") | E66: =IF('House of Quality 3'!$BU$74<>0, 'House of Quality 3'!$BU$74,"") | F66: =IF('House of Quality 3'!$BU$49<>"", 'House of Quality 3'!$BU$49,"")
B67: 12 | C67: =MAX($M90:$CX90) -> 0 | D67: =IF(ISNUMBER($E67), ($E67/SUM($E$56:$E$70))*100, "") | E67: =IF('House of Quality 3'!$CA$74<>0, 'House of Quality 3'!$CA$74,"") | F67: =IF('House of Quality 3'!$CA$49<>"", 'House of Quality 3'!$CA$49,"")
B68: 13 | C68: =MAX($M91:$CX91) -> 0 | D68: =IF(ISNUMBER($E68), ($E68/SUM($E$56:$E$70))*100, "") | E68: =IF('House of Quality 3'!$CG$74<>0, 'House of Quality 3'!$CG$74,"") | F68: =IF('House of Quality 3'!$CG$49<>"", 'House of Quality 3'!$CG$49,"")
B69: 14 | C69: =MAX($M92:$CX92) -> 0 | D69: =IF(ISNUMBER($E69), ($E69/SUM($E$56:$E$70))*100, "") | E69: =IF('House of Quality 3'!$CM$74<>0, 'House of Quality 3'!$CM$74,"") | F69: =IF('House of Quality 3'!$CM$49<>"", 'House of Quality 3'!$CM$49,"")
B70: 15 | C70: =MAX($M93:$CX93) -> 0 | D70: =IF(ISNUMBER($E70), ($E70/SUM($E$56:$E$70))*100, "") | E70: =IF('House of Quality 3'!$CS$74<>0, 'House of Quality 3'!$CS$74,"") | F70: =IF('House of Quality 3'!$CS$49<>"", 'House of Quality 3'!$CS$49,"")
F71: Target or Limit Value
F72: Difficulty (0=Easy to Accomplish, 10=Extremely Difficult)
F73: Max Relationship Value in Column | M73: =MAX(M79:R93) -> 0 | S73: =MAX(S79:X93) -> 0 | Y73: =MAX(Y79:AD93) -> 0 | AE73: =MAX(AE79:AJ93) -> 0 | AK73: =MAX(AK79:AP93) -> 0 | AQ73: =MAX(AQ79:AV93) -> 0 | AW73: =MAX(AW79:BB93) -> 0 | BC73: =MAX(BC79:BH93) -> 0 | BI73: =MAX(BI79:BN93) -> 0 | BO73: =MAX(BO79:BT93) -> 0 | BU73: =MAX(BU79:BZ93) -> 0 | CA73: =MAX(CA79:CF93) -> 0 | CG73: =MAX(CG79:CL93) -> 0 | CM73: =MAX(CM79:CR93) -> 0 | CS73: =MAX(CS79:CX93) -> 0
F74: Weight / Importance | M74: =SUM($D79*M79,$D80*M80,$D81*M81,$D82*M82,$D83*M83,$D84*M84,$D85*M85,$D86*M86,$D87*M87,$D88*M88,$D89*M89,$D90*M90,$D91*M91,$D92*M92,$D93*M93) -> 0 | S74: =SUM($D79*S79,$D80*S80,$D81*S81,$D82*S82,$D83*S83,$D84*S84,$D85*S85,$D86*S86,$D87*S87,$D88*S88,$D89*S89,$D90*S90,$D91*S91,$D92*S92,$D93*S93) -> 0 | Y74: =SUM($D79*Y79,$D80*Y80,$D81*Y81,$D82*Y82,$D83*Y83,$D84*Y84,$D85*Y85,$D86*Y86,$D87*Y87,$D88*Y88,$D89*Y89,$D90*Y90,$D91*Y91,$D92*Y92,$D93*Y93) -> 0 | AE74: =SUM($D79*AE79,$D80*AE80,$D81*AE81,$D82*AE82,$D83*AE83,$D84*AE84,$D85*AE85,$D86*AE86,$D87*AE87,$D88*AE88,$D89*AE89,$D90*AE90,$D91*AE91,$D92*AE92,$D93*AE93) -> 0 | AK74: =SUM($D79*AK79,$D80*AK80,$D81*AK81,$D82*AK82,$D83*AK83,$D84*AK84,$D85*AK85,$D86*AK86,$D87*AK87,$D88*AK88,$D89*AK89,$D90*AK90,$D91*AK91,$D92*AK92,$D93*AK93) -> 0 | AQ74: =SUM($D79*AQ79,$D80*AQ80,$D81*AQ81,$D82*AQ82,$D83*AQ83,$D84*AQ84,$D85*AQ85,$D86*AQ86,$D87*AQ87,$D88*AQ88,$D89*AQ89,$D90*AQ90,$D91*AQ91,$D92*AQ92,$D93*AQ93) -> 0 | AW74: =SUM($D79*AW79,$D80*AW80,$D81*AW81,$D82*AW82,$D83*AW83,$D84*AW84,$D85*AW85,$D86*AW86,$D87*AW87,$D88*AW88,$D89*AW89,$D90*AW90,$D91*AW91,$D92*AW92,$D93*AW93) -> 0 | BC74: =SUM($D79*BC79,$D80*BC80,$D81*BC81,$D82*BC82,$D83*BC83,$D84*BC84,$D85*BC85,$D86*BC86,$D87*BC87,$D88*BC88,$D89*BC89,$D90*BC90,$D91*BC91,$D92*BC92,$D93*BC93) -> 0 | BI74: =SUM($D79*BI79,$D80*BI80,$D81*BI81,$D82*BI82,$D83*BI83,$D84*BI84,$D85*BI85,$D86*BI86,$D87*BI87,$D88*BI88,$D89*BI89,$D90*BI90,$D91*BI91,$D92*BI92,$D93*BI93) -> 0 | BO74: =SUM($D79*BO79,$D80*BO80,$D81*BO81,$D82*BO82,$D83*BO83,$D84*BO84,$D85*BO85,$D86*BO86,$D87*BO87,$D88*BO88,$D89*BO89,$D90*BO90,$D91*BO91,$D92*BO92,$D93*BO93) -> 0 | BU74: =SUM($D79*BU79,$D80*BU80,$D81*BU81,$D82*BU82,$D83*BU83,$D84*BU84,$D85*BU85,$D86*BU86,$D87*BU87,$D88*BU88,$D89*BU89,$D90*BU90,$D91*BU91,$D92*BU92,$D93*BU93) -> 0 | CA74: =SUM($D79*CA79,$D80*CA80,$D81*CA81,$D82*CA82,$D83*CA83,$D84*CA84,$D85*CA85,$D86*CA86,$D87*CA87,$D88*CA88,$D89*CA89,$D90*CA90,$D91*CA91,$D92*CA92,$D93*CA93) -> 0 | CG74: =SUM($D79*CG79,$D80*CG80,$D81*CG81,$D82*CG82,$D83*CG83,$D84*CG84,$D85*CG85,$D86*CG86,$D87*CG87,$D88*CG88,$D89*CG89,$D90*CG90,$D91*CG91,$D92*CG92,$D93*CG93) -> 0 | CM74: =SUM($D79*CM79,$D80*CM80,$D81*CM81,$D82*CM82,$D83*CM83,$D84*CM84,$D85*CM85,$D86*CM86,$D87*CM87,$D88*CM88,$D89*CM89,$D90*CM90,$D91*CM91,$D92*CM92,$D93*CM93) -> 0 | CS74: =SUM($D79*CS79,$D80*CS80,$D81*CS81,$D82*CS82,$D83*CS83,$D84*CS84,$D85*CS85,$D86*CS86,$D87*CS87,$D88*CS88,$D89*CS89,$D90*CS90,$D91*CS91,$D92*CS92,$D93*CS93) -> 0
F75: Relative Weight | M75: =IF(M$74>0,(M$74/SUM($74:$74))*100, "") | S75: =IF(S$74>0,(S$74/SUM($74:$74))*100, "") | Y75: =IF(Y$74>0,(Y$74/SUM($74:$74))*100, "") | AE75: =IF(AE$74>0,(AE$74/SUM($74:$74))*100, "") | AK75: =IF(AK$74>0,(AK$74/SUM($74:$74))*100, "") | AQ75: =IF(AQ$74>0,(AQ$74/SUM($74:$74))*100, "") | AW75: =IF(AW$74>0,(AW$74/SUM($74:$74))*100, "") | BC75: =IF(BC$74>0,(BC$74/SUM($74:$74))*100, "") | BI75: =IF(BI$74>0,(BI$74/SUM($74:$74))*100, "") | BO75: =IF(BO$74>0,(BO$74/SUM($74:$74))*100, "") | BU75: =IF(BU$74>0,(BU$74/SUM($74:$74))*100, "") | CA75: =IF(CA$74>0,(CA$74/SUM($74:$74))*100, "") | CG75: =IF(CG$74>0,(CG$74/SUM($74:$74))*100, "") | CM75: =IF(CM$74>0,(CM$74/SUM($74:$74))*100, "") | CS75: =IF(CS$74>0,(CS$74/SUM($74:$74))*100, "") | CY75: Powered by QFD Online (http://www.QFDOnline.com)
D78: Numeric Values for Relationship Matrix Calculations
D79: =IF($D56<>"",$D56,0) -> 0 | M79: =IF(M56="Θ", 9, IF(M56="Ο", 3, IF(M56="▲", 1, "0"))) -> 0 | S79: =IF(S56="Θ", 9, IF(S56="Ο", 3, IF(S56="▲", 1, "0"))) -> 0 | Y79: =IF(Y56="Θ", 9, IF(Y56="Ο", 3, IF(Y56="▲", 1, "0"))) -> 0 | AE79: =IF(AE56="Θ", 9, IF(AE56="Ο", 3, IF(AE56="▲", 1, "0"))) -> 0 | AK79: =IF(AK56="Θ", 9, IF(AK56="Ο", 3, IF(AK56="▲", 1, "0"))) -> 0 | AQ79: =IF(AQ56="Θ", 9, IF(AQ56="Ο", 3, IF(AQ56="▲", 1, "0"))) -> 0 | AW79: =IF(AW56="Θ", 9, IF(AW56="Ο", 3, IF(AW56="▲", 1, "0"))) -> 0 | BC79: =IF(BC56="Θ", 9, IF(BC56="Ο", 3, IF(BC56="▲", 1, "0"))) -> 0 | BI79: =IF(BI56="Θ", 9, IF(BI56="Ο", 3, IF(BI56="▲", 1, "0"))) -> 0 | BO79: =IF(BO56="Θ", 9, IF(BO56="Ο", 3, IF(BO56="▲", 1, "0"))) -> 0 | BU79: =IF(BU56="Θ", 9, IF(BU56="Ο", 3, IF(BU56="▲", 1, "0"))) -> 0 | CA79: =IF(CA56="Θ", 9, IF(CA56="Ο", 3, IF(CA56="▲", 1, "0"))) -> 0 | CG79: =IF(CG56="Θ", 9, IF(CG56="Ο", 3, IF(CG56="▲", 1, "0"))) -> 0 | CM79: =IF(CM56="Θ", 9, IF(CM56="Ο", 3, IF(CM56="▲", 1, "0"))) -> 0 | CS79: =IF(CS56="Θ", 9, IF(CS56="Ο", 3, IF(CS56="▲", 1, "0"))) -> 0
D80: =IF($D57<>"",$D57,0) -> 0 | M80: =IF(M57="Θ", 9, IF(M57="Ο", 3, IF(M57="▲", 1, "0"))) -> 0 | S80: =IF(S57="Θ", 9, IF(S57="Ο", 3, IF(S57="▲", 1, "0"))) -> 0 | Y80: =IF(Y57="Θ", 9, IF(Y57="Ο", 3, IF(Y57="▲", 1, "0"))) -> 0 | AE80: =IF(AE57="Θ", 9, IF(AE57="Ο", 3, IF(AE57="▲", 1, "0"))) -> 0 | AK80: =IF(AK57="Θ", 9, IF(AK57="Ο", 3, IF(AK57="▲", 1, "0"))) -> 0 | AQ80: =IF(AQ57="Θ", 9, IF(AQ57="Ο", 3, IF(AQ57="▲", 1, "0"))) -> 0 | AW80: =IF(AW57="Θ", 9, IF(AW57="Ο", 3, IF(AW57="▲", 1, "0"))) -> 0 | BC80: =IF(BC57="Θ", 9, IF(BC57="Ο", 3, IF(BC57="▲", 1, "0"))) -> 0 | BI80: =IF(BI57="Θ", 9, IF(BI57="Ο", 3, IF(BI57="▲", 1, "0"))) -> 0 | BO80: =IF(BO57="Θ", 9, IF(BO57="Ο", 3, IF(BO57="▲", 1, "0"))) -> 0 | BU80: =IF(BU57="Θ", 9, IF(BU57="Ο", 3, IF(BU57="▲", 1, "0"))) -> 0 | CA80: =IF(CA57="Θ", 9, IF(CA57="Ο", 3, IF(CA57="▲", 1, "0"))) -> 0 | CG80: =IF(CG57="Θ", 9, IF(CG57="Ο", 3, IF(CG57="▲", 1, "0"))) -> 0 | CM80: =IF(CM57="Θ", 9, IF(CM57="Ο", 3, IF(CM57="▲", 1, "0"))) -> 0 | CS80: =IF(CS57="Θ", 9, IF(CS57="Ο", 3, IF(CS57="▲", 1, "0"))) -> 0
D81: =IF($D58<>"",$D58,0) -> 0 | M81: =IF(M58="Θ", 9, IF(M58="Ο", 3, IF(M58="▲", 1, "0"))) -> 0 | S81: =IF(S58="Θ", 9, IF(S58="Ο", 3, IF(S58="▲", 1, "0"))) -> 0 | Y81: =IF(Y58="Θ", 9, IF(Y58="Ο", 3, IF(Y58="▲", 1, "0"))) -> 0 | AE81: =IF(AE58="Θ", 9, IF(AE58="Ο", 3, IF(AE58="▲", 1, "0"))) -> 0 | AK81: =IF(AK58="Θ", 9, IF(AK58="Ο", 3, IF(AK58="▲", 1, "0"))) -> 0 | AQ81: =IF(AQ58="Θ", 9, IF(AQ58="Ο", 3, IF(AQ58="▲", 1, "0"))) -> 0 | AW81: =IF(AW58="Θ", 9, IF(AW58="Ο", 3, IF(AW58="▲", 1, "0"))) -> 0 | BC81: =IF(BC58="Θ", 9, IF(BC58="Ο", 3, IF(BC58="▲", 1, "0"))) -> 0 | BI81: =IF(BI58="Θ", 9, IF(BI58="Ο", 3, IF(BI58="▲", 1, "0"))) -> 0 | BO81: =IF(BO58="Θ", 9, IF(BO58="Ο", 3, IF(BO58="▲", 1, "0"))) -> 0 | BU81: =IF(BU58="Θ", 9, IF(BU58="Ο", 3, IF(BU58="▲", 1, "0"))) -> 0 | CA81: =IF(CA58="Θ", 9, IF(CA58="Ο", 3, IF(CA58="▲", 1, "0"))) -> 0 | CG81: =IF(CG58="Θ", 9, IF(CG58="Ο", 3, IF(CG58="▲", 1, "0"))) -> 0 | CM81: =IF(CM58="Θ", 9, IF(CM58="Ο", 3, IF(CM58="▲", 1, "0"))) -> 0 | CS81: =IF(CS58="Θ", 9, IF(CS58="Ο", 3, IF(CS58="▲", 1, "0"))) -> 0
...

Sheet About
O3: Template Sponsors:
D7: Template Name: | F7: Traditional House of Quality
D8: Version: | F8: 2.0.346.0
D9: Release Date: | F9: 39427
D11: Updated versions of this template (along with other valuable comments and instruction regarding its use) can be obtained at the following location:
D12: http://www.qfdonline.com/templates/
D14: If you have any questions, comments, requests, or suggestions regarding this template, please submit them via the following discussion forum for this template:
D15: http://www.qfdonline.com/templates/comments/
D17: This template was distributed by QFD Online or one of its Template Sponsors. Resale or redistribution of this template by entities other than QFD Online or its Template Sponsors is strictly prohibited. Inquiries about obtaining redistribution rights to QFD Online's templates can be submitted through the following URL:
D18: http://www.qfdonline.com/templates/template-sponsorship/
D20: Use of this template constitues acceptance of the terms associated with its use, including an understanding that this template is provided "as is" with no warrantees expressed or implied by QFD Online. For a complete list of the terms associated with the use of this template, please visit:
D21: http://www.qfdonline.com/about/terms-of-use/
